Workbook
Name BS_Check: Assumptions!$E$132
Name BS_Check: Scenarios!$E$126
Name BS_Check: Summary!$E$112
Name BS_Check: Model!$E$141
Name Currency: Assumptions!$F$21
Name L_Scenarios: Scenarios!$D$8:$D$10
Name Million: Assumptions!$F$11
Name S_Scenarios: Scenarios!$E$7
Name Scenario_Used: Scenarios!$D$7

Sheet Exam Info
A8: Financial Modeling Institute – AFM Level 1 Exam
A9: Exam Information
A12: Candidate ID: | D12: FMI0178605
A14: Candidate Name: | D14: Ovoke Ohwoganohwo

Sheet Cover Page
B3: =Model!B2 -> Farley-Jamieson Inc.
B5: ="Financial Statement from: "&$D$11+1&" to "&$D$11+5 -> Financial Statement from: 2024 to 2028
B7: Modeler | D7: Ovoke Ohwoganohwo
B9: Version | D9: Ver 1.01
B11: Base Year | D11: 2023
B13: Circularity in Model (OFF) | D13: Net Interest Expense in Income Statement

Sheet Summary
B2: Farley-Jamieson Inc. | I2: ="Financial Model: "&L5&" to "&P5 -> Financial Model: 2024 to 2028
B3: Summary | I3: =IF(BS_Check=0,"BS Check: OK","BS Check: Error") -> BS Check: OK | K3: =Scenario_Used -> Scenario: Base Case
I4: Actual | J4: Actual | K4: Actual | L4: Forecast | M4: Forecast | N4: Forecast | O4: Forecast | P4: Forecast
E5: Unit | F5: Trend | I5: 2021 | J5: =I5+1 -> 2022 | K5: =J5+1 -> 2023 | L5: =K5+1 -> 2024 | M5: =L5+1 -> 2025 | N5: =M5+1 -> 2026 | O5: =N5+1 -> 2027 | P5: =O5+1 -> 2028
B9: Analysis Based On: Base Case
C11: Net Revenue
D12: Net Revenue | E12: $'m | I12: 5118.4 | J12: 5392.4 | K12: 5277.2 | L12: 5839.4112 | M12: 6070.9021 | N12: 6310.318 | O12: 6557.9103 | P12: 6734
D13: Net Revenue Growth Rate | E13: % | J13: 0.053532354 | K13: -0.0213634 | L13: 0.10653589 | M13: 0.039642857 | N13: 0.03943662 | O13: 0.039236111 | P13: 0.026851492
C15: EBITDA
D16: EBITDA | E16: $'m | I16: 817.3 | J16: 909.4 | K16: 779.3 | L16: 1166.1126 | M16: 1203.2135 | N16: 1239.3864 | O16: 1274.4489 | P16: 1258.9381
D17: EBITDA Margin | E17: % | I17: 0.15967881 | J17: 0.16864476 | K17: 0.14767301 | L17: 0.19969696 | M17: 0.19819352 | N17: 0.19640633 | O17: 0.19433765 | P17: 0.1869525
D18: EBITDA Growth Rate | E18: % | J18: 0.11268812 | K18: -0.14306136 | L18: 0.4963591 | M18: 0.031815821 | N18: 0.030063564 | O18: 0.028290201 | P18: -0.012170551
C20: Net Income
D21: Net Income | E21: $'m | I21: 345.7 | J21: 349.5 | K21: 267.2 | L21: 604.21444 | M21: 628.67605 | N21: 654.33978 | O21: 679.87219 | P21: 673.21634
D22: Net Profit Margin | E22: % | I22: 0.067540638 | J22: 0.064813441 | K22: 0.050632911 | L22: 0.10347181 | M22: 0.10355562 | N22: 0.10369363 | O22: 0.10367208 | P22: 0.099972726
D23: Net Income Growth Rate | E23: % | J23: 0.01099219 | K23: -0.23547926 | L23: 1.2612816 | M23: 0.04048498 | N23: 0.040821857 | O23: 0.039020113 | P23: -0.0097898607
C25: Dupont Analysis
D26: ROE | E26: % | I26: 0.19213027 | J26: 0.20526223 | K26: 0.16599366 | L26: 0.31759984 | M26: 0.27720406 | N26: 0.24226001 | O26: 0.21636983 | P26: 0.18805032
D27: Net Profit Margin | E27: % | I27: 0.067540638 | J27: 0.064813441 | K27: 0.050632911 | L27: 0.10347181 | M27: 0.10355562 | N27: 0.10369363 | O27: 0.10367208 | P27: 0.099972726
D28: Assets Turnover | E28: times | I28: 0.92240043 | J28: 0.94719831 | K28: 0.9787092 | L28: 1.0561663 | M28: 1.0623035 | N28: 1.057748 | O28: 1.0519121 | P28: 1.0368487
D29: Financial Leverage | E29: times | I29: 3.0839771 | J29: 3.3435132 | K29: 3.3496925 | L29: 2.9062029 | M29: 2.5291682 | N29: 2.2244776 | O29: 1.9976526 | P29: 1.8267161
B34: Analysis Based On: Best Case
C36: Net Revenue
D37: Net Revenue | E37: $'m | I37: 5118.4 | J37: 5392.4 | K37: 5277.2 | L37: 6486.0192 | M37: 6808.9303 | N37: 7146.4998 | O37: 7307.3 | P37: 7407.4
D38: Net Revenue Growth Rate | E38: % | J38: 0.053532354 | K38: -0.0213634 | L38: 0.2290645 | M38: 0.049785714 | N38: 0.049577465 | O38: 0.02250056 | P38: 0.01369863
C40: EBITDA
D41: EBITDA | E41: $'m | I41: 817.3 | J41: 909.4 | K41: 779.3 | L41: 1826.1095 | M41: 1980.6949 | N41: 2142.3876 | O41: 2182.7863 | P41: 2180.396
D42: EBITDA Margin | E42: % | I42: 0.15967881 | J42: 0.16864476 | K42: 0.14767301 | L42: 0.2815455 | M42: 0.29089664 | N42: 0.29978139 | O42: 0.29871311 | P42: 0.29435376
D43: EBITDA Growth Rate | E43: % | J43: 0.11268812 | K43: -0.14306136 | L43: 1.3432689 | M43: 0.084652876 | N43: 0.081634334 | O43: 0.018856858 | P43: -0.0010950562
C45: Net Income
D46: Net Income | E46: $'m | I46: 345.7 | J46: 349.5 | K46: 267.2 | L46: 1037.3271 | M46: 1145.5276 | N46: 1261.4735 | O46: 1300.3688 | P46: 1312.3573
D47: Net Profit Margin | E47: % | I47: 0.067540638 | J47: 0.064813441 | K47: 0.050632911 | L47: 0.15993278 | M47: 0.168239 | N47: 0.17651627 | O47: 0.17795476 | P47: 0.17716841
D48: Net Income Growth Rate | E48: % | J48: 0.01099219 | K48: -0.23547926 | L48: 2.8822122 | M48: 0.10430706 | N48: 0.10121609 | O48: 0.030833286 | P48: 0.0092192551
C50: Dupont Analysis
D51: ROE | E51: % | I51: 0.19213027 | J51: 0.20526223 | K51: 0.16599366 | L51: 0.47497475 | M51: 0.39735638 | N51: 0.34024015 | O51: 0.28564286 | P51: 0.24279025
D52: Net Profit Margin | E52: % | I52: 0.067540638 | J52: 0.064813441 | K52: 0.050632911 | L52: 0.15993278 | M52: 0.168239 | N52: 0.17651627 | O52: 0.17795476 | P52: 0.17716841
D53: Assets Turnover | E53: times | I53: 0.92240043 | J53: 0.94719831 | K53: 0.9787092 | L53: 1.1165658 | M53: 1.0757889 | N53: 1.024855 | O53: 0.95693855 | P53: 0.89207242
D54: Financial Leverage | E54: times | I54: 3.0839771 | J54: 3.3435132 | K54: 3.3496925 | L54: 2.6597982 | M54: 2.1999055 | N54: 1.8877028 | O54: 1.6833604 | P54: 1.5416227
B59: Analysis Based On: Worst Case
C61: Net Revenue
...

Sheet Assumptions
B2: Farley-Jamieson Inc. | I2: ="Financial Model: "&L5&" to "&P5 -> Financial Model: 2024 to 2028
B3: Assumptions | I3: =IF(BS_Check=0,"BS Check: OK","BS Check: Error") -> BS Check: OK | K3: =Scenario_Used -> Scenario: Base Case
I4: Actual | J4: Actual | K4: Actual | L4: Forecast | M4: Forecast | N4: Forecast | O4: Forecast | P4: Forecast
E5: Unit | F5: Input | I5: 2021 | J5: =I5+1 -> 2022 | K5: =J5+1 -> 2023 | L5: =K5+1 -> 2024 | M5: =L5+1 -> 2025 | N5: =M5+1 -> 2026 | O5: =N5+1 -> 2027 | P5: =O5+1 -> 2028
A8: GENERAL ASSUMPTION
D10: Days in the Year | E10: Days | I10: =DATE(I5,12,31)-DATE(I5,1,1)+1 -> 365 | J10: =DATE(J5,12,31)-DATE(J5,1,1)+1 -> 365 | K10: =DATE(K5,12,31)-DATE(K5,1,1)+1 -> 365 | L10: =DATE(L5,12,31)-DATE(L5,1,1)+1 -> 366 | M10: =DATE(M5,12,31)-DATE(M5,1,1)+1 -> 365 | N10: =DATE(N5,12,31)-DATE(N5,1,1)+1 -> 365 | O10: =DATE(O5,12,31)-DATE(O5,1,1)+1 -> 365 | P10: =DATE(P5,12,31)-DATE(P5,1,1)+1 -> 366
D11: Million | E11: Constant | F11: 1000000
B14: Style Guide
D16: Number | E16: Number | F16: 1234.5
D17: Input | E17: Number
D18: Percentage | E18: Number | F18: 0.123
D19: Multiple | E19: Number | F19: 12.3
D20: Linked | E20: Number
D21: Currency | E21: Number | F21: $'m
D22: Units | E22: Text | F22: Text
D23: Heading 1 | E23: Text | F23: Text
B26: Revenue Assumption
D28: Net Revenue | E28: $/unit | K28: 32421
D29: Gross Revenue | E29: $/unit | K29: 34463
D30: Freight & Warehouse costs | E30: $/unit | K30: 2042
D32: =Scenarios!B33 -> Sales Prices Scenarios | E32: $/unit | L32: =Scenarios!L35 -> 35000 | M32: =Scenarios!M35 -> 35500 | N32: =Scenarios!N35 -> 36000 | O32: =Scenarios!O35 -> 36500 | P32: =Scenarios!P35 -> 37000
D33: =Scenarios!B16 -> Sales Volume Scenarios | E33: % | L33: =Scenarios!L18 -> 0.025 | M33: =Scenarios!M18 -> 0.025 | N33: =Scenarios!N18 -> 0.025 | O33: =Scenarios!O18 -> 0.025 | P33: =Scenarios!P18 -> 0.025
D35: Freight & Warehousing costs | E35: % | L35: =Scenarios!L27 -> 0.03 | M35: =Scenarios!M27 -> 0.03 | N35: =Scenarios!N27 -> 0.03 | O35: =Scenarios!O27 -> 0.03 | P35: =Scenarios!P27 -> 0.03
D37: Manufacturing Capacity | E37: units | F37: 182000
B40: Operating Cost Assumption
C42: Cost of Sales
D43: Variable Cost | E43: % | F43: 0.6
D44: Fixed Cost | E44: % | F44: 0.4
D45: Total Cost | E45: % | F45: =SUM(F43:F44) -> 1
D47: =Scenarios!B25 -> Cost Inflation Scenarios | E47: % | L47: =Scenarios!L27 -> 0.03 | M47: =Scenarios!M27 -> 0.03 | N47: =Scenarios!N27 -> 0.03 | O47: =Scenarios!O27 -> 0.03 | P47: =Scenarios!P27 -> 0.03
D49: Selling General & Administration (“SG&A”) expense | E49: =Currency -> $'m | L49: 1200
B54: Capex and Depreciation Assumption
D56: Capex Additions | E56: =Currency -> $'m | L56: 225 | M56: 225 | N56: 225 | O56: 225 | P56: 225
D58: Depreciation Method | E58: Straight-Line method
C60: Useful Life
D61: Existing assets | E61: Years | F61: 12
D62: New Assets | E62: Years | F62: 18
B65: Income Tax Assumptions
D67: Company’s tax rate | E67: % | F67: 0.35
D69: Reduction due to Timing Differences | E69: =Currency -> $'m | L69: 100 | M69: 100 | N69: 100 | O69: 100 | P69: 100
...

Sheet Scenarios
B2: Farley-Jamieson Inc. | I2: ="Financial Model: "&L5&" to "&P5 -> Financial Model: 2024 to 2028
B3: Scenarios | I3: =IF(BS_Check=0,"BS Check: OK","BS Check: Error") -> BS Check: OK | K3: =Scenario_Used -> Scenario: Base Case
I4: Actual | J4: Actual | K4: Actual | L4: Forecast | M4: Forecast | N4: Forecast | O4: Forecast | P4: Forecast
E5: Unit | F5: Input | I5: 2021 | J5: =I5+1 -> 2022 | K5: =J5+1 -> 2023 | L5: =K5+1 -> 2024 | M5: =L5+1 -> 2025 | N5: =M5+1 -> 2026 | O5: =N5+1 -> 2027 | P5: =O5+1 -> 2028
D7: {="Scenario: "&INDEX(L_Scenarios,S_Scenarios)} -> Scenario: Base Case | E7: 1
D8: Base Case
D9: Best Case
D10: Worst Case
B16: Sales Volume Scenarios
D18: Used in the Model | E18: % | L18: {=INDEX(L19:L21,S_Scenarios)} -> 0.025 | M18: {=INDEX(M19:M21,S_Scenarios)} -> 0.025 | N18: {=INDEX(N19:N21,S_Scenarios)} -> 0.025 | O18: {=INDEX(O19:O21,S_Scenarios)} -> 0.025 | P18: {=INDEX(P19:P21,S_Scenarios)} -> 0.025
D19: {=L_Scenarios} -> Base Case | E19: % | L19: 0.025 | M19: 0.025 | N19: 0.025 | O19: 0.025 | P19: 0.025
D20: Best Case | E20: % | L20: 0.035 | M20: 0.035 | N20: 0.035 | O20: 0.035 | P20: 0.035
D21: Worst Case | E21: % | L21: 0.015 | M21: 0.015 | N21: 0.015 | O21: 0.015 | P21: 0.015
B25: Cost Inflation Scenarios
D27: Used in the Model | E27: % | L27: {=INDEX(L28:L30,S_Scenarios)} -> 0.03 | M27: {=INDEX(M28:M30,S_Scenarios)} -> 0.03 | N27: {=INDEX(N28:N30,S_Scenarios)} -> 0.03 | O27: {=INDEX(O28:O30,S_Scenarios)} -> 0.03 | P27: {=INDEX(P28:P30,S_Scenarios)} -> 0.03
D28: {=L_Scenarios} -> Base Case | E28: % | L28: 0.03 | M28: 0.03 | N28: 0.03 | O28: 0.03 | P28: 0.03
D29: Best Case | E29: % | L29: 0.02 | M29: 0.02 | N29: 0.02 | O29: 0.02 | P29: 0.02
D30: Worst Case | E30: % | L30: 0.04 | M30: 0.04 | N30: 0.04 | O30: 0.04 | P30: 0.04
B33: Sales Prices Scenarios
D35: Used in the Model | E35: $/unit | L35: {=INDEX(L36:L38,S_Scenarios)} -> 35000 | M35: {=INDEX(M36:M38,S_Scenarios)} -> 35500 | N35: {=INDEX(N36:N38,S_Scenarios)} -> 36000 | O35: {=INDEX(O36:O38,S_Scenarios)} -> 36500 | P35: {=INDEX(P36:P38,S_Scenarios)} -> 37000
D36: {=L_Scenarios} -> Base Case | E36: $/unit | L36: 35000 | M36: 35500 | N36: 36000 | O36: 36500 | P36: 37000
D37: Best Case | E37: $/unit | L37: 38500 | M37: 39050 | N37: 39600 | O37: 40150 | P37: 40700
D38: Worst Case | E38: $/unit | L38: 33250 | M38: 33725 | N38: 34200 | O38: 34675 | P38: 35150

Sheet Model
B2: Farley-Jamieson Inc. | I2: ="Financial Model: "&L5&" to "&P5 -> Financial Model: 2024 to 2028
B3: Model | I3: =IF(BS_Check=0,"BS Check: OK","BS Check: Error") -> BS Check: OK | K3: =Scenario_Used -> Scenario: Base Case
I4: Actual | J4: Actual | K4: Actual | L4: Forecast | M4: Forecast | N4: Forecast | O4: Forecast | P4: Forecast
E5: Unit | F5: Input | I5: 2021 | J5: =I5+1 -> 2022 | K5: =J5+1 -> 2023 | L5: =K5+1 -> 2024 | M5: =L5+1 -> 2025 | N5: =M5+1 -> 2026 | O5: =N5+1 -> 2027 | P5: =O5+1 -> 2028
B8: Farley-Jamieson Inc.
B9: Income Statement
B11: Millions for the Year Ended December 31
I13: 2021 | J13: =I13+1 -> 2022 | K13: =J13+1 -> 2023 | L13: =K13+1 -> 2024 | M13: =L13+1 -> 2025 | N13: =M13+1 -> 2026 | O13: =N13+1 -> 2027 | P13: =O13+1 -> 2028
B15: Revenue Growth | E15: % | J15: =J21/I21-1 -> 0.053532354 | K15: =K21/J21-1 -> -0.0213634 | L15: =L21/K21-1 -> 0.10653589 | M15: =M21/L21-1 -> 0.039642857 | N15: =N21/M21-1 -> 0.03943662 | O15: =O21/N21-1 -> 0.039236111 | P15: =P21/O21-1 -> 0.026851492
B16: COGS (% of revenue) | E16: % | I16: =I23/I$21 -> 0.63365505 | J16: =J23/J$21 -> 0.63120317 | K16: =K23/K$21 -> 0.62955734 | L16: =L23/L$21 -> 0.59480287 | M16: =M23/M$21 -> 0.59821235 | N16: =N23/N$21 -> 0.6018479 | O16: =O23/O$21 -> 0.60570957 | P16: =P23/P$21 -> 0.61248163
B17: SG&A (% of revenue) | E17: % | I17: =I24/I$21 -> 0.20545483 | J17: =J24/J$21 -> 0.20015207 | K17: =K24/K$21 -> 0.22276965 | L17: =L24/L$21 -> 0.20550017 | M17: =M24/M$21 -> 0.20359412 | N17: =N24/N$21 -> 0.20174578 | O17: =O24/O$21 -> 0.19995278 | P17: =P24/P$21 -> 0.20056587
D19: Gross Revenue | E19: =Currency -> $'m | I19: 5311.3 | J19: 5610 | K19: 5609.6 | L19: =L173 -> 6181.7832 | M19: =M173 -> 6423.5453 | N19: =N173 -> 6673.5404 | O19: =O173 -> 6932.0295 | P19: =P173 -> 7119.3427
D20: Freight & Warehousing | E20: =Currency -> $'m | I20: 192.9 | J20: 217.6 | K20: 332.4 | L20: =L174 -> 342.372 | M20: =M174 -> 352.64316 | N20: =N174 -> 363.22245 | O20: =O174 -> 374.11913 | P20: =P174 -> 385.3427
D21: Net Revenue | E21: =Currency -> $'m | I21: =I19-I20 -> 5118.4 | J21: =J19-J20 -> 5392.4 | K21: =K19-K20 -> 5277.2 | L21: =L19-L20 -> 5839.4112 | M21: =M19-M20 -> 6070.9021 | N21: =N19-N20 -> 6310.318 | O21: =O19-O20 -> 6557.9103 | P21: =P19-P20 -> 6734
D23: Cost of Sales | E23: =Currency -> $'m | I23: 3243.3 | J23: 3403.7 | K23: 3322.3 | L23: =L196 -> 3473.2985 | M23: =M196 -> 3631.6886 | N23: =N196 -> 3797.8516 | O23: =O196 -> 3972.1891 | P23: =P196 -> 4124.4513
D24: SG&A | E24: =Currency -> $'m | I24: 1051.6 | J24: 1079.3 | K24: 1175.6 | L24: =L198 -> 1200 | M24: =M198 -> 1236 | N24: =N198 -> 1273.08 | O24: =O198 -> 1311.2724 | P24: =P198 -> 1350.6106
D25: Total Costs | E25: =Currency -> $'m | I25: =SUM(I23:I24) -> 4294.9 | J25: =SUM(J23:J24) -> 4483 | K25: =SUM(K23:K24) -> 4497.9 | L25: =SUM(L23:L24) -> 4673.2985 | M25: =SUM(M23:M24) -> 4867.6886 | N25: =SUM(N23:N24) -> 5070.9316 | O25: =SUM(O23:O24) -> 5283.4615 | P25: =SUM(P23:P24) -> 5475.0619
D27: Cost Adjustments - Gain / (Loss) | E27: =Currency -> $'m | I27: -6.2 | J27: 0 | K27: 0 | L27: =Assumptions!L139 -> 0 | M27: =Assumptions!M139 -> 0 | N27: =Assumptions!N139 -> 0 | O27: =Assumptions!O139 -> 0 | P27: =Assumptions!P139 -> 0
D28: EBITDA | E28: =Currency -> $'m | I28: =I21-I25+I27 -> 817.3 | J28: =J21-J25+J27 -> 909.4 | K28: =K21-K25+K27 -> 779.3 | L28: =L21-L25+L27 -> 1166.1126 | M28: =M21-M25+M27 -> 1203.2135 | N28: =N21-N25+N27 -> 1239.3864 | O28: =O21-O25+O27 -> 1274.4489 | P28: =P21-P25+P27 -> 1258.9381
D30: Depreciation | E30: =Currency -> $'m | I30: 165.2 | J30: 151.9 | K30: 158.1 | L30: =L224 -> 18.25 | M30: =M224 -> 30.75 | N30: =N224 -> 43.25 | O30: =O224 -> 55.75 | P30: =P224 -> 68.25
D31: EBIT | E31: =Currency -> $'m | I31: =I28-I30 -> 652.1 | J31: =J28-J30 -> 757.5 | K31: =K28-K30 -> 621.2 | L31: =L28-L30 -> 1147.8626 | M31: =M28-M30 -> 1172.4635 | N31: =N28-N30 -> 1196.1364 | O31: =O28-O30 -> 1218.6989 | P31: =P28-P30 -> 1190.6881
D33: Cost Adjustments - Gain / (Loss) | E33: =Currency -> $'m | I33: 1.5 | J33: 0.6 | K33: 3.2 | L33: =Assumptions!L140 -> 0 | M33: =Assumptions!M140 -> 0 | N33: =Assumptions!N140 -> 0 | O33: =Assumptions!O140 -> 0 | P33: =Assumptions!P140 -> 0
D34: Net Interest Expense | E34: =Currency -> $'m | I34: 138.7 | J34: 216.6 | K34: 225.4 | L34: =L381 -> 218.30197 | M34: =M381 -> 205.26955 | N34: =N381 -> 189.45978 | O34: =O381 -> 172.74164 | P34: =P381 -> 154.97067
D35: EBT | E35: =Currency -> $'m | I35: =I31+I33-I34 -> 514.9 | J35: =J31+J33-J34 -> 541.5 | K35: =K31+K33-K34 -> 399 | L35: =L31+L33-L34 -> 929.56068 | M35: =M31+M33-M34 -> 967.19393 | N35: =N31+N33-N34 -> 1006.6766 | O35: =O31+O33-O34 -> 1045.9572 | P35: =P31+P33-P34 -> 1035.7174
D37: Current Taxes | E37: =Currency -> $'m | I37: 145.8 | J37: 159.4 | K37: 153.1 | L37: =L245 -> 290.34624 | M37: =M245 -> 303.51787 | N37: =N245 -> 317.3368 | O37: =O245 -> 331.08503 | P37: =P245 -> 327.5011
D38: Deferred Income Taxes | E38: =Currency -> $'m | I38: 23.4 | J38: 32.6 | K38: -21.3 | L38: =L246 -> 35 | M38: =M246 -> 35 | N38: =N246 -> 35 | O38: =O246 -> 35 | P38: =P246 -> 35
D39: Total Income Taxes | E39: =Currency -> $'m | I39: =SUM(I37:I38) -> 169.2 | J39: =SUM(J37:J38) -> 192 | K39: =SUM(K37:K38) -> 131.8 | L39: =SUM(L37:L38) -> 325.34624 | M39: =SUM(M37:M38) -> 338.51787 | N39: =SUM(N37:N38) -> 352.3368 | O39: =SUM(O37:O38) -> 366.08503 | P39: =SUM(P37:P38) -> 362.5011
D41: Net Income | E41: =Currency -> $'m | I41: =I35-I39 -> 345.7 | J41: =J35-J39 -> 349.5 | K41: =K35-K39 -> 267.2 | L41: =L35-L39 -> 604.21444 | M41: =M35-M39 -> 628.67605 | N41: =N35-N39 -> 654.33978 | O41: =O35-O39 -> 679.87219 | P41: =P35-P39 -> 673.21634
D43: Preferred Dividend | E43: =Currency -> $'m | I43: 0 | J43: 0 | K43: 0 | L43: =L294 -> 0 | M43: =M294 -> 2.3125 | N43: =N294 -> 4.625 | O43: =O294 -> 4.625 | P43: =P294 -> 4.625
D44: Net Income to Common | E44: =Currency -> $'m | I44: =I41-I43 -> 345.7 | J44: =J41-J43 -> 349.5 | K44: =K41-K43 -> 267.2 | L44: =L41-L43 -> 604.21444 | M44: =M41-M43 -> 626.36355 | N44: =N41-N43 -> 649.71478 | O44: =O41-O43 -> 675.24719 | P44: =P41-P43 -> 668.59134
D47: EBITDA Margin | E47: % | I47: =I28/I21 -> 0.15967881 | J47: =J28/J21 -> 0.16864476 | K47: =K28/K21 -> 0.14767301 | L47: =L28/L21 -> 0.19969696 | M47: =M28/M21 -> 0.19819352 | N47: =N28/N21 -> 0.19640633 | O47: =O28/O21 -> 0.19433765 | P47: =P28/P21 -> 0.1869525
C48: Dupont Analysis
D49: ROE | E49: % | I49: =I44/I135 -> 0.19213027 | J49: =J44/J135 -> 0.20526223 | K49: =K44/K135 -> 0.16599366 | L49: =L44/L135 -> 0.31759984 | M49: =M44/M135 -> 0.27720406 | N49: =N44/N135 -> 0.24226001 | O49: =O44/O135 -> 0.21636983 | P49: =P44/P135 -> 0.18805032
D50: Net Profit Margin | E50: % | I50: =I41/I21 -> 0.067540638 | J50: =J41/J21 -> 0.064813441 | K50: =K41/K21 -> 0.050632911 | L50: =L41/L21 -> 0.10347181 | M50: =M41/M21 -> 0.10355562 | N50: =N41/N21 -> 0.10369363 | O50: =O41/O21 -> 0.10367208 | P50: =P41/P21 -> 0.099972726
D51: Assets Turnover | E51: times | I51: =I21/I114 -> 0.92240043 | J51: =J21/J114 -> 0.94719831 | K51: =K21/K114 -> 0.9787092 | L51: =L21/L114 -> 1.0561663 | M51: =M21/M114 -> 1.0623035 | N51: =N21/N114 -> 1.057748 | O51: =O21/O114 -> 1.0519121 | P51: =P21/P114 -> 1.0368487
D52: Financial Leverage | E52: times | I52: =I114/I135 -> 3.0839771 | J52: =J114/J135 -> 3.3435132 | K52: =K114/K135 -> 3.3496925 | L52: =L114/L135 -> 2.9062029 | M52: =M114/M135 -> 2.5291682 | N52: =N114/N135 -> 2.2244776 | O52: =O114/O135 -> 1.9976526 | P52: =P114/P135 -> 1.8267161
B56: =$B$8 -> Farley-Jamieson Inc.
B57: Cash Flow Statement
B59: =$B$11 -> Millions for the Year Ended December 31
I61: =I$13 -> 2021 | J61: =J$13 -> 2022 | K61: =K$13 -> 2023 | L61: =L$13 -> 2024 | M61: =M$13 -> 2025 | N61: =N$13 -> 2026 | O61: =O$13 -> 2027 | P61: =P$13 -> 2028
...
